2020-02-29 22:07:18,840 INFO: [in /Users/_V/python/flask-tutorial/app/__init__.py:42]
2020-02-29 22:08:05,669 ERROR: [in /Users/_V/.local/share/virtualenvs/flask-tutorial-hMiwqkeU/lib/python3.7/site-packages/flask/app.py:1891]
Traceback (most recent call last):
  File "/Users/_V/.local/share/virtualenvs/flask-tutorial-hMiwqkeU/lib/python3.7/site-packages/sqlalchemy/engine/base.py", line 1246, in _execute_context
    cursor, statement, parameters, context
  File "/Users/_V/.local/share/virtualenvs/flask-tutorial-hMiwqkeU/lib/python3.7/site-packages/sqlalchemy/engine/default.py", line 588, in do_execute
    cursor.execute(statement, parameters)
sqlite3.IntegrityError: UNIQUE constraint failed: user.username

The above exception was the direct cause of the following exception:

Traceback (most recent call last):
  File "/Users/_V/.local/share/virtualenvs/flask-tutorial-hMiwqkeU/lib/python3.7/site-packages/flask/app.py", line 2446, in wsgi_app
    response = self.full_dispatch_request()
  File "/Users/_V/.local/share/virtualenvs/flask-tutorial-hMiwqkeU/lib/python3.7/site-packages/flask/app.py", line 1951, in full_dispatch_request
    rv = self.handle_user_exception(e)
  File "/Users/_V/.local/share/virtualenvs/flask-tutorial-hMiwqkeU/lib/python3.7/site-packages/flask/app.py", line 1820, in handle_user_exception
    reraise(exc_type, exc_value, tb)
  File "/Users/_V/.local/share/virtualenvs/flask-tutorial-hMiwqkeU/lib/python3.7/site-packages/flask/_compat.py", line 39, in reraise
    raise value
  File "/Users/_V/.local/share/virtualenvs/flask-tutorial-hMiwqkeU/lib/python3.7/site-packages/flask/app.py", line 1949, in full_dispatch_request
    rv = self.dispatch_request()
  File "/Users/_V/.local/share/virtualenvs/flask-tutorial-hMiwqkeU/lib/python3.7/site-packages/flask/app.py", line 1935, in dispatch_request
    return self.view_functions[rule.endpoint](**req.view_args)
  File "/Users/_V/.local/share/virtualenvs/flask-tutorial-hMiwqkeU/lib/python3.7/site-packages/flask_login/utils.py", line 272, in decorated_view
    return func(*args, **kwargs)
  File "/Users/_V/python/flask-tutorial/app/routes.py", line 96, in edit_profile
    db.session.commit()
  File "/Users/_V/.local/share/virtualenvs/flask-tutorial-hMiwqkeU/lib/python3.7/site-packages/sqlalchemy/orm/scoping.py", line 162, in do
    return getattr(self.registry(), name)(*args, **kwargs)
  File "/Users/_V/.local/share/virtualenvs/flask-tutorial-hMiwqkeU/lib/python3.7/site-packages/sqlalchemy/orm/session.py", line 1036, in commit
    self.transaction.commit()
  File "/Users/_V/.local/share/virtualenvs/flask-tutorial-hMiwqkeU/lib/python3.7/site-packages/sqlalchemy/orm/session.py", line 503, in commit
    self._prepare_impl()
  File "/Users/_V/.local/share/virtualenvs/flask-tutorial-hMiwqkeU/lib/python3.7/site-packages/sqlalchemy/orm/session.py", line 482, in _prepare_impl
    self.session.flush()
  File "/Users/_V/.local/share/virtualenvs/flask-tutorial-hMiwqkeU/lib/python3.7/site-packages/sqlalchemy/orm/session.py", line 2479, in flush
    self._flush(objects)
  File "/Users/_V/.local/share/virtualenvs/flask-tutorial-hMiwqkeU/lib/python3.7/site-packages/sqlalchemy/orm/session.py", line 2617, in _flush
    transaction.rollback(_capture_exception=True)
  File "/Users/_V/.local/share/virtualenvs/flask-tutorial-hMiwqkeU/lib/python3.7/site-packages/sqlalchemy/util/langhelpers.py", line 68, in __exit__
    compat.reraise(exc_type, exc_value, exc_tb)
  File "/Users/_V/.local/share/virtualenvs/flask-tutorial-hMiwqkeU/lib/python3.7/site-packages/sqlalchemy/util/compat.py", line 153, in reraise
    raise value
  File "/Users/_V/.local/share/virtualenvs/flask-tutorial-hMiwqkeU/lib/python3.7/site-packages/sqlalchemy/orm/session.py", line 2577, in _flush
    flush_context.execute()
  File "/Users/_V/.local/share/virtualenvs/flask-tutorial-hMiwqkeU/lib/python3.7/site-packages/sqlalchemy/orm/unitofwork.py", line 422, in execute
    rec.execute(self)
  File "/Users/_V/.local/share/virtualenvs/flask-tutorial-hMiwqkeU/lib/python3.7/site-packages/sqlalchemy/orm/unitofwork.py", line 589, in execute
    uow,
  File "/Users/_V/.local/share/virtualenvs/flask-tutorial-hMiwqkeU/lib/python3.7/site-packages/sqlalchemy/orm/persistence.py", line 236, in save_obj
    update,
  File "/Users/_V/.local/share/virtualenvs/flask-tutorial-hMiwqkeU/lib/python3.7/site-packages/sqlalchemy/orm/persistence.py", line 996, in _emit_update_statements
    statement, multiparams
  File "/Users/_V/.local/share/virtualenvs/flask-tutorial-hMiwqkeU/lib/python3.7/site-packages/sqlalchemy/engine/base.py", line 982, in execute
    return meth(self, multiparams, params)
  File "/Users/_V/.local/share/virtualenvs/flask-tutorial-hMiwqkeU/lib/python3.7/site-packages/sqlalchemy/sql/elements.py", line 293, in _execute_on_connection
    return connection._execute_clauseelement(self, multiparams, params)
  File "/Users/_V/.local/share/virtualenvs/flask-tutorial-hMiwqkeU/lib/python3.7/site-packages/sqlalchemy/engine/base.py", line 1101, in _execute_clauseelement
    distilled_params,
  File "/Users/_V/.local/share/virtualenvs/flask-tutorial-hMiwqkeU/lib/python3.7/site-packages/sqlalchemy/engine/base.py", line 1250, in _execute_context
    e, statement, parameters, cursor, context
  File "/Users/_V/.local/share/virtualenvs/flask-tutorial-hMiwqkeU/lib/python3.7/site-packages/sqlalchemy/engine/base.py", line 1476, in _handle_dbapi_exception
    util.raise_from_cause(sqlalchemy_exception, exc_info)
  File "/Users/_V/.local/share/virtualenvs/flask-tutorial-hMiwqkeU/lib/python3.7/site-packages/sqlalchemy/util/compat.py", line 398, in raise_from_cause
    reraise(type(exception), exception, tb=exc_tb, cause=cause)
  File "/Users/_V/.local/share/virtualenvs/flask-tutorial-hMiwqkeU/lib/python3.7/site-packages/sqlalchemy/util/compat.py", line 152, in reraise
    raise value.with_traceback(tb)
  File "/Users/_V/.local/share/virtualenvs/flask-tutorial-hMiwqkeU/lib/python3.7/site-packages/sqlalchemy/engine/base.py", line 1246, in _execute_context
    cursor, statement, parameters, context
  File "/Users/_V/.local/share/virtualenvs/flask-tutorial-hMiwqkeU/lib/python3.7/site-packages/sqlalchemy/engine/default.py", line 588, in do_execute
    cursor.execute(statement, parameters)
sqlalchemy.exc.IntegrityError: (sqlite3.IntegrityError) UNIQUE constraint failed: user.username
[SQL: UPDATE user SET username=?, about_me=? WHERE user.id = ?]
[parameters: ('test', '', 4)]
(Background on this error at: http://sqlalche.me/e/gkpj)
